Workbook

Sheet Start Here
A1: Farm Intelligence Source Registry
A3: What this is | B3: A working list of trusted sources for supply, demand, price, trade and driver signals that affect farms, tagged by commodity group, driver, horizon, and trust tier.
A4: Tabs | B4: Source Registry (the list) | Driver Coverage (live counts, including independence) | Root Check (test whether sources are really independent) | MVP Sources (the first 15 sources, by build wave) | Trigger Map (trigger families and the sources that detect them) | Lens to Sources (how the strategic lens selects sources) | Policy Map (policy levers and coverage by commodity) | Policy Alert Rules (when a policy item becomes an alert) | Coverage Checklist (what the registry should cover, and where gaps remain) | Commodity Nodes (upstream, co-products, downstream)
A5: What to edit | B5: Yellow cells in the Pipeline status column (and the source ID cells on Root Check). Update status as sources move from scoped to connected to live. Add new rows at the bottom of the registry; the coverage tab recalculates.
A6: Authority tier 1 | B6: Official statistic: government or intergovernmental data. Authoritative, but lags.
A7: Authority tier 2 | B7: Market price, exchange, or trade-body data and structured analyst baselines. Timely, with method caveats.
A8: Authority tier 3 | B8: Analyst or advocacy interpretation. Useful for context; label as opinion.
A9: Retrieval tier | B9: 0 = synthesized house sources (driver briefs, Future State material, diversification library); 1 = curated secondary sources (outlooks, analysis, advocacy, news); 2 = primary data. Agents look in this order and use tier 2 only to fetch a current value, fill a gap, or verify. This is separate from authority tier.
A10: System role | B10: Detection feed = watched to detect triggers. Context = used to explain and frame. Context (synthesized) = retrieval tier 0. Fetch and verify = pulled on demand. Lens prefill = proposes strategic lens fields for the farmer to confirm.
A11: Trigger family | B11: The kind of dynamic change a source helps detect or explain. Policy and regulation is its own family. The Trigger Map tab counts sources by family.
A12: Lens selector and MFP dimension | B12: Which part of the farm's strategic lens decides whether a source is on that farm's watch list, and which MFP dimension the source helps. The Lens to Sources tab explains the logic.
A13: Cache life | B13: How long a fetched value may be reused before it is fetched again.
A14: MVP wave | B14: The 15 sources recommended for the first build, in three waves (yellow, editable). The MVP Sources tab lists them with access watch-outs.
... A22: Caveats | B22: URLs are entry-point pages listed from general knowledge and were not link-checked in this build. Confirm each URL, release schedule, and API terms before automating. Source types, cadences, and access terms change.
A24: Registry rows: | B24: =COUNTA('Source Registry'!$A$2:$A$300) -> 188

Sheet Source Registry
A1: ID | B1: Source | C1: Publisher | D1: Commodity group | E1: Layer | F1: Primary driver | G1: Horizon | H1: Source type | I1: Authority tier | J1: Update cadence | K1: Access | L1: URL | M1: What it answers | N1: Notes | O1: Origin | P1: Depends on | Q1: Root ID | R1: Independent signal | S1: What it adds | T1: Pipeline status | U1: Trigger family | V1: System role | W1: Retrieval tier | X1: Lens selector | Y1: MFP dimension served | Z1: Cache life | AA1: MVP wave | AB1: MVP watch-out
A2: S001 | B2: WASDE | C2: USDA OCE / WAOB | D2: Cross-commodity | E2: Balance sheet | F2: Core S&D (baseline) | G2: Near-term (1-2 seasons) | H2: Official statistic | I2: 1 | J2: Monthly | K2: Free download | L2: https://www.usda.gov/oce/commodity/wasde | M2: US and world supply, use, ending stocks and price forecasts for grains, oilseeds, livestock, dairy, sugar, cotton | N2: The monthly benchmark; release dates are published a year ahead | O2: Mixed | P2: S003, S025, S026, S027 | Q2: S001 | R2: Partial | S2: Forecast | T2: Not started | U2: Context only | V2: Fetch and verify | W2: 2 | X2: All farms (context) | Y2: Strategic Vision; Market Analysis | Z2: Days to weeks
A3: S002 | B3: PSD Online | C3: USDA FAS | D3: Cross-commodity | E3: Balance sheet | F3: Core S&D (baseline) | G3: Both | H3: Official statistic | I3: 1 | J3: Monthly | K3: Free API / download | L3: https://apps.fas.usda.gov/psdonline/ | M3: Production, supply and distribution by country (about 200 countries) for major commodities | N3: Global view behind WASDE | O3: Mixed | P3: S003, S025, S027 | Q3: S001 | R3: No | S3: Repackaging | T3: Not started | U3: Context only | V3: Fetch and verify | W3: 2 | X3: All farms (context) | Y3: Strategic Vision; Market Analysis | Z3: Days to weeks
A4: S003 | B4: NASS Quick Stats | C4: USDA NASS | D4: Cross-commodity | E4: Balance sheet | F4: Core S&D (baseline) | G4: Both | H4: Official statistic | I4: 1 | J4: Varies by series | K4: Free API | L4: https://quickstats.nass.usda.gov/ | M4: Production, area, inventories, prices received, by state and county | N4: Best structured API for US farm statistics | O4: Original measurement | Q4: S003 | R4: Yes | S4: New data | T4: Not started | U4: Context only | V4: Fetch and verify | W4: 2 | X4: All farms (context) | Y4: Strategic Vision; Market Analysis | Z4: Days to weeks
A5: S004 | B5: NASS Crop Progress and Grain Stocks | C5: USDA NASS | D5: Grains & oilseeds | E5: Balance sheet | F5: Core S&D (baseline) | G5: Near-term (1-2 seasons) | H5: Official statistic | I5: 1 | J5: Weekly (season) / quarterly | K5: Free download | L5: https://www.nass.usda.gov/Publications/ | M5: Planting and condition ratings, on-farm and off-farm grain stocks | N5: Crop condition is an early yield signal | O5: Original measurement | Q5: S004 | R5: Yes | S5: New data | T5: Not started | U5: Context only | V5: Fetch and verify | W5: 2 | X5: All farms (context) | Y5: Strategic Vision; Market Analysis | Z5: Days to weeks
A6: S005 | B6: NASS Cattle, Cattle on Feed, Hogs and Pigs | C6: USDA NASS | D6: Livestock & poultry | E6: Balance sheet | F6: Core S&D (baseline) | G6: Near-term (1-2 seasons) | H6: Official statistic | I6: 1 | J6: Monthly / quarterly / semiannual | K6: Free API / download | L6: https://www.nass.usda.gov/Publications/ | M6: Herd and inventory size, placements, marketings | N6: Herd size drives multi-year supply | O6: Original measurement | Q6: S005 | R6: Yes | S6: New data | T6: Not started | U6: Context only | V6: Fetch and verify | W6: 2 | X6: All farms (context) | Y6: Strategic Vision; Market Analysis | Z6: Days to weeks
A7: S006 | B7: NASS Milk Production and Dairy Products | C7: USDA NASS | D7: Dairy | E7: Balance sheet | F7: Core S&D (baseline) | G7: Near-term (1-2 seasons) | H7: Official statistic | I7: 1 | J7: Monthly | K7: Free API / download | L7: https://www.nass.usda.gov/Publications/ | M7: Milk output, cow numbers, cheese, butter, whey and dry product production | N7: Whey output follows cheese output | O7: Original measurement | Q7: S006 | R7: Yes | S7: New data | T7: Not started | U7: Context only | V7: Fetch and verify | W7: 2 | X7: All farms (context) | Y7: Strategic Vision; Market Analysis | Z7: Days to weeks
A8: S007 | B8: ERS Dairy and Livestock Outlooks | C8: USDA ERS | D8: Dairy | E8: Balance sheet | F8: Core S&D (baseline) | G8: Near-term (1-2 seasons) | H8: Official statistic | I8: 1 | J8: Monthly | K8: Free download | L8: https://www.ers.usda.gov/topics/animal-products/dairy/ | M8: Dairy, livestock, poultry outlook narrative and data tables | N8: Good plain-English context for WASDE numbers | O8: Derived | P8: S001, S006, S017, S005 | Q8: S001 | R8: No | S8: Interpretation | T8: Not started | U8: Context only | V8: Context | W8: 1 | X8: All farms (context) | Y8: Strategic Vision; Market Analysis | Z8: Days to weeks
A9: S008 | B9: ERS Crop Outlooks (feed, wheat, oil crops) | C9: USDA ERS | D9: Grains & oilseeds | E9: Balance sheet | F9: Core S&D (baseline) | G9: Near-term (1-2 seasons) | H9: Official statistic | I9: 1 | J9: Monthly | K9: Free download | L9: https://www.ers.usda.gov/topics/crops/ | M9: Commodity-level outlook, use breakdown, trade | N9: Check the topic page for the current report list | O9: Derived | P9: S001, S003, S026 | Q9: S001 | R9: No | S9: Interpretation | T9: Not started | U9: Context only | V9: Context | W9: 1 | X9: All farms (context) | Y9: Strategic Vision; Market Analysis | Z9: Days to weeks
A10: S009 | B10: ERS Fruit, Tree Nut and Vegetable Outlooks | C10: USDA ERS | D10: Specialty crops | E10: Balance sheet | F10: Core S&D (baseline) | G10: Both | H10: Official statistic | I10: 1 | J10: Periodic | K10: Free download | L10: https://www.ers.usda.gov/topics/crops/ | M10: Production, imports, per-capita use for specialty crops | N10: Fewer formal balance sheets than field crops | O10: Derived | P10: S003, S020, S028 | Q10: S003 | R10: Partial | S10: Interpretation | T10: Not started | U10: Context only | V10: Context | W10: 1 | X10: All farms (context) | Y10: Strategic Vision; Market Analysis | Z10: Days to weeks
A11: S010 | B11: ERS Food Price Outlook | C11: USDA ERS | D11: Cross-commodity | E11: Demand signal | F11: Human Health | G11: Near-term (1-2 seasons) | H11: Official statistic | I11: 1 | J11: Monthly | K11: Free download | L11: https://www.ers.usda.gov/data-products/food-price-outlook/ | M11: Retail food price forecasts by category | N11: Consumer-side price pressure | O11: Mixed | P11: S139 | Q11: S010 | R11: Partial | S11: Forecast | T11: Not started | U11: Context only | V11: Context | W11: 1 | X11: All farms (context) | Y11: Strategic Vision; Market Analysis | Z11: Days to weeks
A12: S011 | B12: ERS Food Availability (per capita) | C12: USDA ERS | D12: Cross-commodity | E12: Demand signal | F12: Human Health | G12: Long-term (3-10 yrs) | H12: Official statistic | I12: 1 | J12: Annual | K12: Free download | L12: https://www.ers.usda.gov/data-products/food-availability-per-capita-data-system/ | M12: Long-run US food consumption by commodity | N12: Shows protein, dairy and sweetener demand shifts | O12: Derived | P12: S003, S028 | Q12: S003 | R12: Partial | S12: Repackaging | T12: Not started | U12: Context only | V12: Fetch and verify | W12: 2 | X12: All farms (context) | Y12: Strategic Vision; Market Analysis | Z12: Days to weeks
A13: S012 | B13: ERS Farm Income Forecast | C13: USDA ERS | D13: Farm economy | E13: Economy | F13: Core S&D (baseline) | G13: Near-term (1-2 seasons) | H13: Official statistic | I13: 1 | J13: Quarterly | K13: Free download | L13: https://www.ers.usda.gov/data-products/farm-income-and-wealth-statistics/ | M13: Net farm income, expenses, debt, government payments | N13: Farm financial health baseline | O13: Derived | P13: S003, S001 | Q13: S003 | R13: Partial | S13: Forecast | T13: Not started | U13: Credit and finance | V13: Context | W13: 1 | X13: Debt and financial health | Y13: Financial Analysis; Risk & Protection | Z13: Days to weeks
A14: S013 | B14: ERS International Macroeconomic Data Set | C14: USDA ERS | D14: Cross-commodity | E14: Demand signal | F14: Global Affluence | G14: Long-term (3-10 yrs) | H14: Official statistic | I14: 1 | J14: Annual | K14: Free download | L14: https://www.ers.usda.gov/data-products/international-macroeconomic-data-set/ | M14: GDP, income and population projections by country | N14: Feeds import-demand projections | O14: Derived | P14: S052, S053 | Q14: S052 | R14: No | S14: Repackaging | T14: Not started | U14: Context only | V14: Fetch and verify | W14: 2 | X14: All farms (context) | Y14: Strategic Vision; Market Analysis | Z14: Days to weeks
A15: S014 | B15: Census of Agriculture | C15: USDA NASS | D15: Ownership | E15: Structure | F15: Ownership | G15: Long-term (3-10 yrs) | H15: Official statistic | I15: 1 | J15: Every 5 years | K15: Free download | L15: https://www.nass.usda.gov/AgCensus/ | M15: Farm numbers, size, operator age, ownership and tenure | N15: Core data for consolidation and succession trends | O15: Original measurement | Q15: S014 | R15: Yes | S15: New data | T15: Not started | U15: Land and ownership | V15: Fetch and verify | W15: 2 | X15: Land tenure and legacy intent | Y15: Succession; Financial Analysis | Z15: Weeks to months
A16: S015 | B16: NASS Land Values | C16: USDA NASS | D16: Ownership | E16: Structure | F16: Ownership | G16: Both | H16: Official statistic | I16: 1 | J16: Annual | K16: Free download | L16: https://www.nass.usda.gov/Publications/ | M16: Cropland and pasture values and cash rents by state | N16: Asset-side view of farm balance sheets | O16: Original measurement | Q16: S015 | R16: Yes | S16: New data | T16: Not started | U16: Land and ownership | V16: Fetch and verify | W16: 2 | X16: Land tenure and legacy intent | Y16: Succession; Financial Analysis | Z16: Weeks to months
A17: S016 | B17: AFIDA reports | C17: USDA FSA | D17: Ownership | E17: Structure | F17: Ownership | G17: Long-term (3-10 yrs) | H17: Official statistic | I17: 1 | J17: Annual | K17: Free download | L17: https://www.fsa.usda.gov/ | M17: Foreign holdings of US agricultural land | N17: Verify current report location before automating | O17: Original measurement | Q17: S016 | R17: Yes | S17: New data | T17: Not started | U17: Land and ownership | V17: Fetch and verify | W17: 2 | X17: Land tenure and legacy intent | Y17: Succession; Financial Analysis | Z17: Weeks to months
A18: S017 | B18: AMS Dairy Market News | C18: USDA AMS | D18: Dairy | E18: Price & market | F18: Core S&D (baseline) | G18: Near-term (1-2 seasons) | H18: Market price / trade data | I18: 2 | J18: Weekly / daily | K18: Free API (MARS) / web | L18: https://www.ams.usda.gov/market-news/dairy-market-news | M18: Prices and volumes for dry whey, WPC34/80, WPI, lactose, NDM, butter, cheese; cold storage | N18: Primary source for whey and derived dairy products | O18: Market-generated | Q18: S017 | R18: Yes | S18: Timing | T18: Not started | U18: Price and market | V18: Detection feed | W18: 2 | X18: Enterprises and income shares | Y18: Market Analysis | Z18: Minutes to hours | AA18: Wave 1
A19: S018 | B19: AMS Livestock, Poultry and Grain Market News | C19: USDA AMS | D19: Livestock & poultry | E19: Price & market | F19: Core S&D (baseline) | G19: Near-term (1-2 seasons) | H19: Market price / trade data | I19: 2 | J19: Daily / weekly | K19: Free API (MARS) / web | L19: https://www.ams.usda.gov/market-news | M19: Cash prices, boxed beef cutout, slaughter, grain bids | N19: Includes livestock mandatory reporting | O19: Market-generated | Q19: S018 | R19: Yes | S19: Timing | T19: Not started | U19: Price and market | V19: Detection feed | W19: 2 | X19: Enterprises and income shares | Y19: Market Analysis | Z19: Minutes to hours | AA19: Wave 1
A20: S019 | B20: AMS Egg Markets Overview | C20: USDA AMS | D20: Livestock & poultry | E20: Price & market | F20: Core S&D (baseline) | G20: Near-term (1-2 seasons) | H20: Market price / trade data | I20: 2 | J20: Weekly | K20: Free web | L20: https://www.ams.usda.gov/market-news | M20: Egg prices, flock and supply conditions | N20: Pairs with HPAI status from APHIS | O20: Market-generated | Q20: S019 | R20: Yes | S20: Timing | T20: Not started | U20: Price and market | V20: Detection feed | W20: 2 | X20: Enterprises and income shares | Y20: Market Analysis | Z20: Minutes to hours
A21: S020 | B21: AMS Specialty Crops Market News | C21: USDA AMS | D21: Specialty crops | E21: Price & market | F21: Core S&D (baseline) | G21: Near-term (1-2 seasons) | H21: Market price / trade data | I21: 2 | J21: Daily | K21: Free API (MARS) / web | L21: https://www.ams.usda.gov/market-news | M21: Terminal and shipping-point prices, volumes, origin | N21: Main price source for fruit and vegetables | O21: Market-generated | Q21: S020 | R21: Yes | S21: Timing | T21: Not started | U21: Price and market | V21: Detection feed | W21: 2 | X21: Enterprises and income shares | Y21: Market Analysis | Z21: Minutes to hours
A22: S021 | B22: AMS fertilizer and production cost reports | C22: USDA AMS | D22: Inputs | E22: Price & market | F22: Core S&D (baseline) | G22: Near-term (1-2 seasons) | H22: Market price / trade data | I22: 2 | J22: Bi-weekly / weekly | K22: Free web | L22: https://www.ams.usda.gov/market-news | M22: Retail and regional fertilizer prices | N22: Check which regional reports are current | O22: Market-generated | Q22: S021 | R22: Yes | S22: Timing | T22: Not started | U22: Input cost | V22: Fetch and verify | W22: 2 | X22: Cost structure and enterprises | Y22: Financial Analysis; Adoption & Efficiency | Z22: Hours to a day
A23: S022 | B23: CME dairy futures and spot | C23: CME Group | D23: Dairy | E23: Price & market | F23: Core S&D (baseline) | G23: Near-term (1-2 seasons) | H23: Market price / trade data | I23: 2 | J23: Daily | K23: Delayed free / real-time licensed | L23: https://www.cmegroup.com/markets/agriculture.html | M23: Class III and IV milk, cheese, butter, NDM, dry whey futures; forward curve | N23: Futures curve shows what the market pays to wait | O23: Market-generated | P23: S017, S006 | Q23: S022 | R23: Partial | S23: Timing | T23: Not started | U23: Price and market | V23: Detection feed | W23: 2 | X23: Enterprises and income shares | Y23: Market Analysis | Z23: Minutes to hours | AA23: Wave 2 | AB23: Confirm CME data licensing for display in a commercial product; fall back to AMS feeds
A24: S023 | B24: CME grain and livestock futures | C24: CME Group | D24: Grains & oilseeds | E24: Price & market | F24: Core S&D (baseline) | G24: Near-term (1-2 seasons) | H24: Market price / trade data | I24: 2 | J24: Daily | K24: Delayed free / real-time licensed | L24: https://www.cmegroup.com/markets/agriculture.html | M24: Corn, soy, wheat, live and feeder cattle, lean hogs | N24: Use curve shape and basis, not just front month | O24: Market-generated | P24: S001 | Q24: S023 | R24: Partial | S24: Timing | T24: Not started | U24: Price and market | V24: Detection feed | W24: 2 | X24: Enterprises and income shares | Y24: Market Analysis | Z24: Minutes to hours | AA24: Wave 2 | AB24: Confirm CME data licensing for display in a commercial product; fall back to AMS feeds
A25: S024 | B25: Global Dairy Trade auctions | C25: Global Dairy Trade | D25: Dairy | E25: Price & market | F25: Geopolitics | G25: Near-term (1-2 seasons) | H25: Market price / trade data | I25: 2 | J25: Twice monthly | K25: Free web | L25: https://www.globaldairytrade.info/ | M25: International dairy commodity price signal | N25: Reflects New Zealand, EU and other exporter supply | O25: Market-generated | Q25: S024 | R25: Yes | S25: Timing | T25: Not started | U25: Price and market | V25: Detection feed | W25: 2 | X25: Enterprises and income shares | Y25: Market Analysis | Z25: Minutes to hours | AA25: Wave 2 | AB25: Web-only; check terms and plan for licensed access or careful scraping
A26: S025 | B26: GATS (Global Agricultural Trade System) | C26: USDA FAS | D26: Cross-commodity | E26: Trade flow | F26: Geopolitics | G26: Both | H26: Official statistic | I26: 1 | J26: Monthly | K26: Free download | L26: https://apps.fas.usda.gov/gats/ | M26: US exports and imports by product (HS code), country, value and volume | N26: Confirm HS codes: whey, milk albumins and lactose sit in different chapters | O26: Derived | P26: S028 | Q26: S028 | R26: No | S26: Repackaging | T26: Not started | U26: Trade and geopolitics | V26: Fetch and verify | W26: 2 | X26: Products sold, buyers, and inputs bought | Y26: Market Analysis | Z26: Until the action changes
A27: S026 | B27: FAS Export Sales Reporting | C27: USDA FAS | D27: Grains & oilseeds | E27: Trade flow | F27: Geopolitics | G27: Near-term (1-2 seasons) | H27: Official statistic | I27: 1 | J27: Weekly | K27: Free download | L27: https://apps.fas.usda.gov/export-sales/esrd1.html | M27: Weekly commitments and shipments by destination | N27: Fast read on buyer demand, such as China and Mexico | O27: Original measurement | Q27: S026 | R27: Yes | S27: Timing | T27: Not started | U27: Trade and geopolitics | V27: Detection feed | W27: 2 | X27: Products sold, buyers, and inputs bought | Y27: Market Analysis | Z27: Until the action changes | AA27: Wave 3
A28: S027 | B28: FAS GAIN reports | C28: USDA FAS attaches | D28: Cross-commodity | E28: Trade flow | F28: Geopolitics | G28: Both | H28: Official statistic | I28: 1 | J28: Continuous | K28: Free download | L28: https://gain.fas.usda.gov/ | M28: Country-level reports on policy, crops, and market access from overseas staff | N28: One of the best on-the-ground geopolitical sources | O28: Original measurement | Q28: S027 | R28: Yes | S28: New data | T28: Not started | U28: Trade and geopolitics | V28: Detection feed | W28: 2 | X28: Products sold, buyers, and inputs bought | Y28: Market Analysis | Z28: Until the action changes
A29: S028 | B29: Census Bureau trade data | C29: US Census Bureau | D29: Cross-commodity | E29: Trade flow | F29: Geopolitics | G29: Both | H29: Official statistic | I29: 1 | J29: Monthly | K29: Free API / download | L29: https://www.census.gov/foreign-trade/index.html | M29: US trade by HS code and partner | N29: Cross-check against GATS | O29: Original measurement | Q29: S028 | R29: Yes | S29: New data | T29: Not started | U29: Trade and geopolitics | V29: Fetch and verify | W29: 2 | X29: Products sold, buyers, and inputs bought | Y29: Market Analysis | Z29: Until the action changes
A30: S029 | B30: UN Comtrade | C30: United Nations | D30: Cross-commodity | E30: Trade flow | F30: Geopolitics | G30: Long-term (3-10 yrs) | H30: Official statistic | I30: 1 | J30: Monthly / annual | K30: Free tier API / paid tiers | L30: https://comtradeplus.un.org/ | M30: Global trade flows between country pairs | N30: Needed to see competitors and third-country demand | O30: Derived | P30: S028 | Q30: S029 | R30: Partial | S30: New data | T30: Not started | U30: Trade and geopolitics | V30: Fetch and verify | W30: 2 | X30: Products sold, buyers, and inputs bought | Y30: Market Analysis | Z30: Until the action changes
A31: S030 | B31: USDEC data and analysis | C31: US Dairy Export Council | D31: Dairy | E31: Trade flow | F31: Global Affluence | G31: Both | H31: Analyst view | I31: 3 | J31: Monthly | K31: Mixed (members / public) | L31: https://www.usdec.org/ | M31: US dairy export trends by product and market | N31: Strong on whey and ingredient exports | O31: Mixed | P31: S025, S028 | Q31: S028 | R31: Partial | S31: Interpretation | T31: Not started | U31: Trade and geopolitics | V31: Context | W31: 1 | X31: Products sold, buyers, and inputs bought | Y31: Market Analysis | Z31: Until the action changes
A32: S031 | B32: FAOSTAT | C32: FAO | D32: Cross-commodity | E32: Balance sheet | F32: Core S&D (baseline) | G32: Long-term (3-10 yrs) | H32: Official statistic | I32: 1 | J32: Annual | K32: Free API / download | L32: https://www.fao.org/faostat/ | M32: Global production, trade, food balances | N32: Lags by months to a year | O32: Derived | Q32: S031 | R32: Partial | S32: New data | T32: Not started | U32: Context only | V32: Fetch and verify | W32: 2 | X32: All farms (context) | Y32: Strategic Vision; Market Analysis | Z32: Days to weeks
A33: S032 | B33: FAO Food Price Index | C33: FAO | D33: Cross-commodity | E33: Price & market | F33: Core S&D (baseline) | G33: Near-term (1-2 seasons) | H33: Official statistic | I33: 1 | J33: Monthly | K33: Free download | L33: https://www.fao.org/worldfoodsituation/foodpricesindex/en/ | M33: Global food price index by commodity group | N33: Useful global price context | O33: Derived | Q33: S032 | R33: Partial | S33: Repackaging | T33: Not started | U33: Price and market | V33: Fetch and verify | W33: 2 | X33: Enterprises and income shares | Y33: Market Analysis | Z33: Minutes to hours
A34: S033 | B34: OECD-FAO Agricultural Outlook | C34: OECD / FAO | D34: Cross-commodity | E34: Outlook | F34: Global Affluence | G34: Long-term (3-10 yrs) | H34: Analyst view | I34: 2 | J34: Annual | K34: Free download | L34: https://www.agri-outlook.org/ | M34: 10-year projections of production, use, trade, prices | N34: Baseline for long-term drivers | O34: Mixed | P34: S001, S002, S031 | Q34: S033 | R34: Partial | S34: Forecast | T34: Not started | U34: Context only | V34: Context | W34: 1 | X34: All farms (context) | Y34: Strategic Vision; Market Analysis | Z34: Days to weeks
A35: S034 | B35: FAPRI baseline | C35: University of Missouri | D35: Cross-commodity | E35: Outlook | F35: Core S&D (baseline) | G35: Long-term (3-10 yrs) | H35: Analyst view | I35: 2 | J35: Annual | K35: Free download | L35: https://www.fapri.missouri.edu/ | M35: US baseline projections and policy scenarios | N35: Good for farm bill and policy what-ifs | O35: Mixed | P35: S001, S003 | Q35: S001 | R35: Partial | S35: Forecast | T35: Not started | U35: Context only | V35: Context | W35: 1 | X35: All farms (context) | Y35: Strategic Vision; Market Analysis | Z35: Days to weeks
A36: S035 | B36: EIA weekly ethanol and energy data | C36: US EIA | D36: Grains & oilseeds | E36: Demand signal | F36: Technology | G36: Near-term (1-2 seasons) | H36: Official statistic | I36: 1 | J36: Weekly | K36: Free API | L36: https://www.eia.gov/opendata/ | M36: Ethanol production and stocks; energy prices | N36: Ethanol is a major corn demand channel | O36: Original measurement | Q36: S035 | R36: Yes | S36: Timing | T36: Not started | U36: Price and market | V36: Detection feed | W36: 2 | X36: Enterprises and income shares | Y36: Market Analysis | Z36: Minutes to hours
A37: S036 | B37: NOPA crush report | C37: National Oilseed Processors Association | D37: Grains & oilseeds | E37: Demand signal | F37: Technology | G37: Near-term (1-2 seasons) | H37: Market price / trade data | I37: 2 | J37: Monthly | K37: Free web | L37: https://www.nopa.org/ | M37: US soybean crush, meal and oil stocks | N37: Shows crush demand tied to biofuel and feed | O37: Original measurement | Q37: S036 | R37: Yes | S37: New data | T37: Not started | U37: Price and market | V37: Fetch and verify | W37: 2 | X37: Enterprises and income shares | Y37: Market Analysis | Z37: Minutes to hours
A38: S037 | B38: EPA Renewable Fuel Standard | C38: US EPA | D38: Grains & oilseeds | E38: Policy | F38: Cross-driver | G38: Both | H38: Official statistic | I38: 1 | J38: Event-driven | K38: Free web | L38: https://www.epa.gov/renewable-fuel-standard-program | M38: Biofuel blending requirements that drive soy oil and corn demand | N38: Policy changes can move demand fast | O38: Original measurement | Q38: S037 | R38: Yes | S38: New data | T38: Not started | U38: Policy and regulation | V38: Detection feed | W38: 2 | X38: Enterprises, size class, and diversification paths | Y38: Risk & Protection; Income Diversification | Z38: Until the status changes
A39: S038 | B39: CONAB crop reports | C39: Brazil CONAB | D39: Grains & oilseeds | E39: Balance sheet | F39: Core S&D (baseline) | G39: Near-term (1-2 seasons) | H39: Official statistic | I39: 1 | J39: Monthly | K39: Free download | L39: https://www.conab.gov.br/ | M39: Brazil crop estimates (soy, corn) | N39: Main competitor supply signal | O39: Original measurement | Q39: S038 | R39: Yes | S39: New data | T39: Not started | U39: Context only | V39: Fetch and verify | W39: 2 | X39: All farms (context) | Y39: Strategic Vision; Market Analysis | Z39: Days to weeks
A40: S039 | B40: Argentine grain exchange reports | C40: Buenos Aires and Rosario exchanges | D40: Grains & oilseeds | E40: Balance sheet | F40: Core S&D (baseline) | G40: Near-term (1-2 seasons) | H40: Analyst view | I40: 2 | J40: Weekly | K40: Free web | L40: https://www.bolsadecereales.com/ | M40: Argentina crop condition and estimates | N40: Spanish-language; useful for competitor supply | O40: Original measurement | Q40: S039 | R40: Yes | S40: New data | T40: Not started | U40: Context only | V40: Fetch and verify | W40: 2 | X40: All farms (context) | Y40: Strategic Vision; Market Analysis | Z40: Days to weeks
...

Sheet MVP Sources
A1: MVP sources: the first 15, by build wave
A2: Chosen for dynamic sources and authority tier 2 where it exists. Wave is set in the Source Registry (MVP wave column); this tab reads from it.
A4: Wave | B4: ID | C4: Source | D4: Authority tier | E4: Cadence | F4: Trigger family | G4: System role | H4: Access | I4: Watch-out before building
A5: =IFERROR(INDEX('Source Registry'!$AA$2:$AA$400,MATCH($B5,'Source Registry'!$A$2:$A$400,0))&"","") -> Wave 1 | B5: S018 | C5: =IFERROR(INDEX('Source Registry'!$B$2:$B$400,MATCH($B5,'Source Registry'!$A$2:$A$400,0))&"","") -> AMS Livestock, Poultry and Grain Market News | D5: =IFERROR(INDEX('Source Registry'!$I$2:$I$400,MATCH($B5,'Source Registry'!$A$2:$A$400,0))&"","") -> 2 | E5: =IFERROR(INDEX('Source Registry'!$J$2:$J$400,MATCH($B5,'Source Registry'!$A$2:$A$400,0))&"","") -> Daily / weekly | F5: =IFERROR(INDEX('Source Registry'!$U$2:$U$400,MATCH($B5,'Source Registry'!$A$2:$A$400,0))&"","") -> Price and market | G5: =IFERROR(INDEX('Source Registry'!$V$2:$V$400,MATCH($B5,'Source Registry'!$A$2:$A$400,0))&"","") -> Detection feed | H5: =IFERROR(INDEX('Source Registry'!$K$2:$K$400,MATCH($B5,'Source Registry'!$A$2:$A$400,0))&"","") -> Free API (MARS) / web | I5: =IFERROR(INDEX('Source Registry'!$AB$2:$AB$400,MATCH($B5,'Source Registry'!$A$2:$A$400,0))&"","")
A6: =IFERROR(INDEX('Source Registry'!$AA$2:$AA$400,MATCH($B6,'Source Registry'!$A$2:$A$400,0))&"","") -> Wave 1 | B6: S017 | C6: =IFERROR(INDEX('Source Registry'!$B$2:$B$400,MATCH($B6,'Source Registry'!$A$2:$A$400,0))&"","") -> AMS Dairy Market News | D6: =IFERROR(INDEX('Source Registry'!$I$2:$I$400,MATCH($B6,'Source Registry'!$A$2:$A$400,0))&"","") -> 2 | E6: =IFERROR(INDEX('Source Registry'!$J$2:$J$400,MATCH($B6,'Source Registry'!$A$2:$A$400,0))&"","") -> Weekly / daily | F6: =IFERROR(INDEX('Source Registry'!$U$2:$U$400,MATCH($B6,'Source Registry'!$A$2:$A$400,0))&"","") -> Price and market | G6: =IFERROR(INDEX('Source Registry'!$V$2:$V$400,MATCH($B6,'Source Registry'!$A$2:$A$400,0))&"","") -> Detection feed | H6: =IFERROR(INDEX('Source Registry'!$K$2:$K$400,MATCH($B6,'Source Registry'!$A$2:$A$400,0))&"","") -> Free API (MARS) / web | I6: =IFERROR(INDEX('Source Registry'!$AB$2:$AB$400,MATCH($B6,'Source Registry'!$A$2:$A$400,0))&"","")
A7: =IFERROR(INDEX('Source Registry'!$AA$2:$AA$400,MATCH($B7,'Source Registry'!$A$2:$A$400,0))&"","") -> Wave 1 | B7: S057 | C7: =IFERROR(INDEX('Source Registry'!$B$2:$B$400,MATCH($B7,'Source Registry'!$A$2:$A$400,0))&"","") -> Federal Register | D7: =IFERROR(INDEX('Source Registry'!$I$2:$I$400,MATCH($B7,'Source Registry'!$A$2:$A$400,0))&"","") -> 1 | E7: =IFERROR(INDEX('Source Registry'!$J$2:$J$400,MATCH($B7,'Source Registry'!$A$2:$A$400,0))&"","") -> Daily | F7: =IFERROR(INDEX('Source Registry'!$U$2:$U$400,MATCH($B7,'Source Registry'!$A$2:$A$400,0))&"","") -> Policy and regulation | G7: =IFERROR(INDEX('Source Registry'!$V$2:$V$400,MATCH($B7,'Source Registry'!$A$2:$A$400,0))&"","") -> Detection feed | H7: =IFERROR(INDEX('Source Registry'!$K$2:$K$400,MATCH($B7,'Source Registry'!$A$2:$A$400,0))&"","") -> Free API | I7: =IFERROR(INDEX('Source Registry'!$AB$2:$AB$400,MATCH($B7,'Source Registry'!$A$2:$A$400,0))&"","")
A8: =IFERROR(INDEX('Source Registry'!$AA$2:$AA$400,MATCH($B8,'Source Registry'!$A$2:$A$400,0))&"","") -> Wave 1 | B8: S114 | C8: =IFERROR(INDEX('Source Registry'!$B$2:$B$400,MATCH($B8,'Source Registry'!$A$2:$A$400,0))&"","") -> National Weather Service forecasts and alerts | D8: =IFERROR(INDEX('Source Registry'!$I$2:$I$400,MATCH($B8,'Source Registry'!$A$2:$A$400,0))&"","") -> 1 | E8: =IFERROR(INDEX('Source Registry'!$J$2:$J$400,MATCH($B8,'Source Registry'!$A$2:$A$400,0))&"","") -> Continuous | F8: =IFERROR(INDEX('Source Registry'!$U$2:$U$400,MATCH($B8,'Source Registry'!$A$2:$A$400,0))&"","") -> Weather and climate | G8: =IFERROR(INDEX('Source Registry'!$V$2:$V$400,MATCH($B8,'Source Registry'!$A$2:$A$400,0))&"","") -> Detection feed | H8: =IFERROR(INDEX('Source Registry'!$K$2:$K$400,MATCH($B8,'Source Registry'!$A$2:$A$400,0))&"","") -> Free API | I8: =IFERROR(INDEX('Source Registry'!$AB$2:$AB$400,MATCH($B8,'Source Registry'!$A$2:$A$400,0))&"","")
A9: =IFERROR(INDEX('Source Registry'!$AA$2:$AA$400,MATCH($B9,'Source Registry'!$A$2:$A$400,0))&"","") -> Wave 1 | B9: S065 | C9: =IFERROR(INDEX('Source Registry'!$B$2:$B$400,MATCH($B9,'Source Registry'!$A$2:$A$400,0))&"","") -> US Drought Monitor | D9: =IFERROR(INDEX('Source Registry'!$I$2:$I$400,MATCH($B9,'Source Registry'!$A$2:$A$400,0))&"","") -> 1 | E9: =IFERROR(INDEX('Source Registry'!$J$2:$J$400,MATCH($B9,'Source Registry'!$A$2:$A$400,0))&"","") -> Weekly | F9: =IFERROR(INDEX('Source Registry'!$U$2:$U$400,MATCH($B9,'Source Registry'!$A$2:$A$400,0))&"","") -> Weather and climate | G9: =IFERROR(INDEX('Source Registry'!$V$2:$V$400,MATCH($B9,'Source Registry'!$A$2:$A$400,0))&"","") -> Detection feed | H9: =IFERROR(INDEX('Source Registry'!$K$2:$K$400,MATCH($B9,'Source Registry'!$A$2:$A$400,0))&"","") -> Free download / API | I9: =IFERROR(INDEX('Source Registry'!$AB$2:$AB$400,MATCH($B9,'Source Registry'!$A$2:$A$400,0))&"","")
A10: =IFERROR(INDEX('Source Registry'!$AA$2:$AA$400,MATCH($B10,'Source Registry'!$A$2:$A$400,0))&"","") -> Wave 1 | B10: S041 | C10: =IFERROR(INDEX('Source Registry'!$B$2:$B$400,MATCH($B10,'Source Registry'!$A$2:$A$400,0))&"","") -> DTN retail fertilizer trends | D10: =IFERROR(INDEX('Source Registry'!$I$2:$I$400,MATCH($B10,'Source Registry'!$A$2:$A$400,0))&"","") -> 2 | E10: =IFERROR(INDEX('Source Registry'!$J$2:$J$400,MATCH($B10,'Source Registry'!$A$2:$A$400,0))&"","") -> Weekly | F10: =IFERROR(INDEX('Source Registry'!$U$2:$U$400,MATCH($B10,'Source Registry'!$A$2:$A$400,0))&"","") -> Input cost | G10: =IFERROR(INDEX('Source Registry'!$V$2:$V$400,MATCH($B10,'Source Registry'!$A$2:$A$400,0))&"","") -> Detection feed | H10: =IFERROR(INDEX('Source Registry'!$K$2:$K$400,MATCH($B10,'Source Registry'!$A$2:$A$400,0))&"","") -> Free web | I10: =IFERROR(INDEX('Source Registry'!$AB$2:$AB$400,MATCH($B10,'Source Registry'!$A$2:$A$400,0))&"","") -> Web-only; check terms and plan for licensed access or careful scraping
A11: =IFERROR(INDEX('Source Registry'!$AA$2:$AA$400,MATCH($B11,'Source Registry'!$A$2:$A$400,0))&"","") -> Wave 2 | B11: S023 | C11: =IFERROR(INDEX('Source Registry'!$B$2:$B$400,MATCH($B11,'Source Registry'!$A$2:$A$400,0))&"","") -> CME grain and livestock futures | D11: =IFERROR(INDEX('Source Registry'!$I$2:$I$400,MATCH($B11,'Source Registry'!$A$2:$A$400,0))&"","") -> 2 | E11: =IFERROR(INDEX('Source Registry'!$J$2:$J$400,MATCH($B11,'Source Registry'!$A$2:$A$400,0))&"","") -> Daily | F11: =IFERROR(INDEX('Source Registry'!$U$2:$U$400,MATCH($B11,'Source Registry'!$A$2:$A$400,0))&"","") -> Price and market | G11: =IFERROR(INDEX('Source Registry'!$V$2:$V$400,MATCH($B11,'Source Registry'!$A$2:$A$400,0))&"","") -> Detection feed | H11: =IFERROR(INDEX('Source Registry'!$K$2:$K$400,MATCH($B11,'Source Registry'!$A$2:$A$400,0))&"","") -> Delayed free / real-time licensed | I11: =IFERROR(INDEX('Source Registry'!$AB$2:$AB$400,MATCH($B11,'Source Registry'!$A$2:$A$400,0))&"","") -> Confirm CME data licensing for display in a commercial product; fall back to AMS feeds
A12: =IFERROR(INDEX('Source Registry'!$AA$2:$AA$400,MATCH($B12,'Source Registry'!$A$2:$A$400,0))&"","") -> Wave 2 | B12: S022 | C12: =IFERROR(INDEX('Source Registry'!$B$2:$B$400,MATCH($B12,'Source Registry'!$A$2:$A$400,0))&"","") -> CME dairy futures and spot | D12: =IFERROR(INDEX('Source Registry'!$I$2:$I$400,MATCH($B12,'Source Registry'!$A$2:$A$400,0))&"","") -> 2 | E12: =IFERROR(INDEX('Source Registry'!$J$2:$J$400,MATCH($B12,'Source Registry'!$A$2:$A$400,0))&"","") -> Daily | F12: =IFERROR(INDEX('Source Registry'!$U$2:$U$400,MATCH($B12,'Source Registry'!$A$2:$A$400,0))&"","") -> Price and market | G12: =IFERROR(INDEX('Source Registry'!$V$2:$V$400,MATCH($B12,'Source Registry'!$A$2:$A$400,0))&"","") -> Detection feed | H12: =IFERROR(INDEX('Source Registry'!$K$2:$K$400,MATCH($B12,'Source Registry'!$A$2:$A$400,0))&"","") -> Delayed free / real-time licensed | I12: =IFERROR(INDEX('Source Registry'!$AB$2:$AB$400,MATCH($B12,'Source Registry'!$A$2:$A$400,0))&"","") -> Confirm CME data licensing for display in a commercial product; fall back to AMS feeds
A13: =IFERROR(INDEX('Source Registry'!$AA$2:$AA$400,MATCH($B13,'Source Registry'!$A$2:$A$400,0))&"","") -> Wave 2 | B13: S024 | C13: =IFERROR(INDEX('Source Registry'!$B$2:$B$400,MATCH($B13,'Source Registry'!$A$2:$A$400,0))&"","") -> Global Dairy Trade auctions | D13: =IFERROR(INDEX('Source Registry'!$I$2:$I$400,MATCH($B13,'Source Registry'!$A$2:$A$400,0))&"","") -> 2 | E13: =IFERROR(INDEX('Source Registry'!$J$2:$J$400,MATCH($B13,'Source Registry'!$A$2:$A$400,0))&"","") -> Twice monthly | F13: =IFERROR(INDEX('Source Registry'!$U$2:$U$400,MATCH($B13,'Source Registry'!$A$2:$A$400,0))&"","") -> Price and market | G13: =IFERROR(INDEX('Source Registry'!$V$2:$V$400,MATCH($B13,'Source Registry'!$A$2:$A$400,0))&"","") -> Detection feed | H13: =IFERROR(INDEX('Source Registry'!$K$2:$K$400,MATCH($B13,'Source Registry'!$A$2:$A$400,0))&"","") -> Free web | I13: =IFERROR(INDEX('Source Registry'!$AB$2:$AB$400,MATCH($B13,'Source Registry'!$A$2:$A$400,0))&"","") -> Web-only; check terms and plan for licensed access or careful scraping
A14: =IFERROR(INDEX('Source Registry'!$AA$2:$AA$400,MATCH($B14,'Source Registry'!$A$2:$A$400,0))&"","") -> Wave 2 | B14: S153 | C14: =IFERROR(INDEX('Source Registry'!$B$2:$B$400,MATCH($B14,'Source Registry'!$A$2:$A$400,0))&"","") -> AMS hay and feedstuffs reports | D14: =IFERROR(INDEX('Source Registry'!$I$2:$I$400,MATCH($B14,'Source Registry'!$A$2:$A$400,0))&"","") -> 2 | E14: =IFERROR(INDEX('Source Registry'!$J$2:$J$400,MATCH($B14,'Source Registry'!$A$2:$A$400,0))&"","") -> Weekly | F14: =IFERROR(INDEX('Source Registry'!$U$2:$U$400,MATCH($B14,'Source Registry'!$A$2:$A$400,0))&"","") -> Input cost | G14: =IFERROR(INDEX('Source Registry'!$V$2:$V$400,MATCH($B14,'Source Registry'!$A$2:$A$400,0))&"","") -> Detection feed | H14: =IFERROR(INDEX('Source Registry'!$K$2:$K$400,MATCH($B14,'Source Registry'!$A$2:$A$400,0))&"","") -> Free web / API | I14: =IFERROR(INDEX('Source Registry'!$AB$2:$AB$400,MATCH($B14,'Source Registry'!$A$2:$A$400,0))&"","") -> Confirm report names and API access
A15: =IFERROR(INDEX('Source Registry'!$AA$2:$AA$400,MATCH($B15,'Source Registry'!$A$2:$A$400,0))&"","") -> Wave 2 | B15: S072 | C15: =IFERROR(INDEX('Source Registry'!$B$2:$B$400,MATCH($B15,'Source Registry'!$A$2:$A$400,0))&"","") -> Congress.gov | D15: =IFERROR(INDEX('Source Registry'!$I$2:$I$400,MATCH($B15,'Source Registry'!$A$2:$A$400,0))&"","") -> 1 | E15: =IFERROR(INDEX('Source Registry'!$J$2:$J$400,MATCH($B15,'Source Registry'!$A$2:$A$400,0))&"","") -> Daily | F15: =IFERROR(INDEX('Source Registry'!$U$2:$U$400,MATCH($B15,'Source Registry'!$A$2:$A$400,0))&"","") -> Policy and regulation | G15: =IFERROR(INDEX('Source Registry'!$V$2:$V$400,MATCH($B15,'Source Registry'!$A$2:$A$400,0))&"","") -> Detection feed | H15: =IFERROR(INDEX('Source Registry'!$K$2:$K$400,MATCH($B15,'Source Registry'!$A$2:$A$400,0))&"","") -> Free web / API | I15: =IFERROR(INDEX('Source Registry'!$AB$2:$AB$400,MATCH($B15,'Source Registry'!$A$2:$A$400,0))&"","")
A16: =IFERROR(INDEX('Source Registry'!$AA$2:$AA$400,MATCH($B16,'Source Registry'!$A$2:$A$400,0))&"","") -> Wave 2 | B16: S093 | C16: =IFERROR(INDEX('Source Registry'!$B$2:$B$400,MATCH($B16,'Source Registry'!$A$2:$A$400,0))&"","") -> LegiScan | D16: =IFERROR(INDEX('Source Registry'!$I$2:$I$400,MATCH($B16,'Source Registry'!$A$2:$A$400,0))&"","") -> 2 | E16: =IFERROR(INDEX('Source Registry'!$J$2:$J$400,MATCH($B16,'Source Registry'!$A$2:$A$400,0))&"","") -> Daily | F16: =IFERROR(INDEX('Source Registry'!$U$2:$U$400,MATCH($B16,'Source Registry'!$A$2:$A$400,0))&"","") -> Policy and regulation | G16: =IFERROR(INDEX('Source Registry'!$V$2:$V$400,MATCH($B16,'Source Registry'!$A$2:$A$400,0))&"","") -> Detection feed | H16: =IFERROR(INDEX('Source Registry'!$K$2:$K$400,MATCH($B16,'Source Registry'!$A$2:$A$400,0))&"","") -> Free tier / paid API | I16: =IFERROR(INDEX('Source Registry'!$AB$2:$AB$400,MATCH($B16,'Source Registry'!$A$2:$A$400,0))&"","") -> Free tier has limits
... A19: =IFERROR(INDEX('Source Registry'!$AA$2:$AA$400,MATCH($B19,'Source Registry'!$A$2:$A$400,0))&"","") -> Wave 3 | B19: S040 | C19: =IFERROR(INDEX('Source Registry'!$B$2:$B$400,MATCH($B19,'Source Registry'!$A$2:$A$400,0))&"","") -> APHIS animal health data | D19: =IFERROR(INDEX('Source Registry'!$I$2:$I$400,MATCH($B19,'Source Registry'!$A$2:$A$400,0))&"","") -> 1 | E19: =IFERROR(INDEX('Source Registry'!$J$2:$J$400,MATCH($B19,'Source Registry'!$A$2:$A$400,0))&"","") -> Event-driven | F19: =IFERROR(INDEX('Source Registry'!$U$2:$U$400,MATCH($B19,'Source Registry'!$A$2:$A$400,0))&"","") -> Disease and border | G19: =IFERROR(INDEX('Source Registry'!$V$2:$V$400,MATCH($B19,'Source Registry'!$A$2:$A$400,0))&"","") -> Detection feed | H19: =IFERROR(INDEX('Source Registry'!$K$2:$K$400,MATCH($B19,'Source Registry'!$A$2:$A$400,0))&"","") -> Free web | I19: =IFERROR(INDEX('Source Registry'!$AB$2:$AB$400,MATCH($B19,'Source Registry'!$A$2:$A$400,0))&"","") -> Web notices with no clear API; check terms
A22: Summary
A23: Sources in the MVP | C23: =COUNTA($B$5:$B$19) -> 15
A24: Authority tier 2 | C24: =COUNTIF($D$5:$D$19,"2") -> 9
A25: Authority tier 1 | C25: =COUNTIF($D$5:$D$19,"1") -> 6
A26: Wave 1 | C26: =COUNTIF($A$5:$A$19,"Wave 1") -> 6
A27: Wave 2 | C27: =COUNTIF($A$5:$A$19,"Wave 2") -> 6
A28: Wave 3 | C28: =COUNTIF($A$5:$A$19,"Wave 3") -> 3
A29: Trigger families covered | C29: =SUMPRODUCT(1/COUNTIF($F$5:$F$19,$F$5:$F$19)) -> 6
A31: Not in the MVP, first to add next: WASDE (verification baseline), eggs and specialty crops (if a pilot farm needs them), credit sources, and Regulations.gov for comment dockets.

Sheet Driver Coverage
A1: Driver coverage: how many registered sources back each driver
A2: All counts are formulas over the Source Registry. Add or change rows there and these update.
A4: Driver | B4: Total sources | C4: Authority 1 (official) | D4: Authority 2 (market / trade) | E4: Authority 3 (analyst) | F4: Near-term | G4: Long-term | H4: Both horizons | I4: Connected or live | J4: % connected or live
A5: Global Affluence | B5: =COUNTIF('Source Registry'!$F$2:$F$300,$A5) -> 14 | C5: =COUNTIFS('Source Registry'!$F$2:$F$300,$A5,'Source Registry'!$I$2:$I$300,1) -> 7 | D5: =COUNTIFS('Source Registry'!$F$2:$F$300,$A5,'Source Registry'!$I$2:$I$300,2) -> 5 | E5: =COUNTIFS('Source Registry'!$F$2:$F$300,$A5,'Source Registry'!$I$2:$I$300,3) -> 2 | F5: =COUNTIFS('Source Registry'!$F$2:$F$300,$A5,'Source Registry'!$G$2:$G$300,"Near-term (1-2 seasons)") -> 1 | G5: =COUNTIFS('Source Registry'!$F$2:$F$300,$A5,'Source Registry'!$G$2:$G$300,"Long-term (3-10 yrs)") -> 7 | H5: =COUNTIFS('Source Registry'!$F$2:$F$300,$A5,'Source Registry'!$G$2:$G$300,"Both") -> 6 | I5: =COUNTIFS('Source Registry'!$F$2:$F$300,$A5,'Source Registry'!$T$2:$T$300,"Connected")+COUNTIFS('Source Registry'!$F$2:$F$300,$A5,'Source Registry'!$T$2:$T$300,"Live in agent") -> 0 | J5: =IF(B5=0,0,I5/B5) -> 0
A6: Geopolitics | B6: =COUNTIF('Source Registry'!$F$2:$F$300,$A6) -> 19 | C6: =COUNTIFS('Source Registry'!$F$2:$F$300,$A6,'Source Registry'!$I$2:$I$300,1) -> 15 | D6: =COUNTIFS('Source Registry'!$F$2:$F$300,$A6,'Source Registry'!$I$2:$I$300,2) -> 4 | E6: =COUNTIFS('Source Registry'!$F$2:$F$300,$A6,'Source Registry'!$I$2:$I$300,3) -> 0 | F6: =COUNTIFS('Source Registry'!$F$2:$F$300,$A6,'Source Registry'!$G$2:$G$300,"Near-term (1-2 seasons)") -> 6 | G6: =COUNTIFS('Source Registry'!$F$2:$F$300,$A6,'Source Registry'!$G$2:$G$300,"Long-term (3-10 yrs)") -> 3 | H6: =COUNTIFS('Source Registry'!$F$2:$F$300,$A6,'Source Registry'!$G$2:$G$300,"Both") -> 10 | I6: =COUNTIFS('Source Registry'!$F$2:$F$300,$A6,'Source Registry'!$T$2:$T$300,"Connected")+COUNTIFS('Source Registry'!$F$2:$F$300,$A6,'Source Registry'!$T$2:$T$300,"Live in agent") -> 0 | J6: =IF(B6=0,0,I6/B6) -> 0
A7: Human Health | B7: =COUNTIF('Source Registry'!$F$2:$F$300,$A7) -> 16 | C7: =COUNTIFS('Source Registry'!$F$2:$F$300,$A7,'Source Registry'!$I$2:$I$300,1) -> 8 | D7: =COUNTIFS('Source Registry'!$F$2:$F$300,$A7,'Source Registry'!$I$2:$I$300,2) -> 6 | E7: =COUNTIFS('Source Registry'!$F$2:$F$300,$A7,'Source Registry'!$I$2:$I$300,3) -> 2 | F7: =COUNTIFS('Source Registry'!$F$2:$F$300,$A7,'Source Registry'!$G$2:$G$300,"Near-term (1-2 seasons)") -> 3 | G7: =COUNTIFS('Source Registry'!$F$2:$F$300,$A7,'Source Registry'!$G$2:$G$300,"Long-term (3-10 yrs)") -> 5 | H7: =COUNTIFS('Source Registry'!$F$2:$F$300,$A7,'Source Registry'!$G$2:$G$300,"Both") -> 8 | I7: =COUNTIFS('Source Registry'!$F$2:$F$300,$A7,'Source Registry'!$T$2:$T$300,"Connected")+COUNTIFS('Source Registry'!$F$2:$F$300,$A7,'Source Registry'!$T$2:$T$300,"Live in agent") -> 0 | J7: =IF(B7=0,0,I7/B7) -> 0
A8: Climate Volatility | B8: =COUNTIF('Source Registry'!$F$2:$F$300,$A8) -> 32 | C8: =COUNTIFS('Source Registry'!$F$2:$F$300,$A8,'Source Registry'!$I$2:$I$300,1) -> 25 | D8: =COUNTIFS('Source Registry'!$F$2:$F$300,$A8,'Source Registry'!$I$2:$I$300,2) -> 7 | E8: =COUNTIFS('Source Registry'!$F$2:$F$300,$A8,'Source Registry'!$I$2:$I$300,3) -> 0 | F8: =COUNTIFS('Source Registry'!$F$2:$F$300,$A8,'Source Registry'!$G$2:$G$300,"Near-term (1-2 seasons)") -> 19 | G8: =COUNTIFS('Source Registry'!$F$2:$F$300,$A8,'Source Registry'!$G$2:$G$300,"Long-term (3-10 yrs)") -> 7 | H8: =COUNTIFS('Source Registry'!$F$2:$F$300,$A8,'Source Registry'!$G$2:$G$300,"Both") -> 6 | I8: =COUNTIFS('Source Registry'!$F$2:$F$300,$A8,'Source Registry'!$T$2:$T$300,"Connected")+COUNTIFS('Source Registry'!$F$2:$F$300,$A8,'Source Registry'!$T$2:$T$300,"Live in agent") -> 0 | J8: =IF(B8=0,0,I8/B8) -> 0
A9: Technology | B9: =COUNTIF('Source Registry'!$F$2:$F$300,$A9) -> 11 | C9: =COUNTIFS('Source Registry'!$F$2:$F$300,$A9,'Source Registry'!$I$2:$I$300,1) -> 6 | D9: =COUNTIFS('Source Registry'!$F$2:$F$300,$A9,'Source Registry'!$I$2:$I$300,2) -> 3 | E9: =COUNTIFS('Source Registry'!$F$2:$F$300,$A9,'Source Registry'!$I$2:$I$300,3) -> 2 | F9: =COUNTIFS('Source Registry'!$F$2:$F$300,$A9,'Source Registry'!$G$2:$G$300,"Near-term (1-2 seasons)") -> 2 | G9: =COUNTIFS('Source Registry'!$F$2:$F$300,$A9,'Source Registry'!$G$2:$G$300,"Long-term (3-10 yrs)") -> 4 | H9: =COUNTIFS('Source Registry'!$F$2:$F$300,$A9,'Source Registry'!$G$2:$G$300,"Both") -> 5 | I9: =COUNTIFS('Source Registry'!$F$2:$F$300,$A9,'Source Registry'!$T$2:$T$300,"Connected")+COUNTIFS('Source Registry'!$F$2:$F$300,$A9,'Source Registry'!$T$2:$T$300,"Live in agent") -> 0 | J9: =IF(B9=0,0,I9/B9) -> 0
A10: Ownership | B10: =COUNTIF('Source Registry'!$F$2:$F$300,$A10) -> 16 | C10: =COUNTIFS('Source Registry'!$F$2:$F$300,$A10,'Source Registry'!$I$2:$I$300,1) -> 9 | D10: =COUNTIFS('Source Registry'!$F$2:$F$300,$A10,'Source Registry'!$I$2:$I$300,2) -> 4 | E10: =COUNTIFS('Source Registry'!$F$2:$F$300,$A10,'Source Registry'!$I$2:$I$300,3) -> 3 | F10: =COUNTIFS('Source Registry'!$F$2:$F$300,$A10,'Source Registry'!$G$2:$G$300,"Near-term (1-2 seasons)") -> 6 | G10: =COUNTIFS('Source Registry'!$F$2:$F$300,$A10,'Source Registry'!$G$2:$G$300,"Long-term (3-10 yrs)") -> 5 | H10: =COUNTIFS('Source Registry'!$F$2:$F$300,$A10,'Source Registry'!$G$2:$G$300,"Both") -> 5 | I10: =COUNTIFS('Source Registry'!$F$2:$F$300,$A10,'Source Registry'!$T$2:$T$300,"Connected")+COUNTIFS('Source Registry'!$F$2:$F$300,$A10,'Source Registry'!$T$2:$T$300,"Live in agent") -> 0 | J10: =IF(B10=0,0,I10/B10) -> 0
A11: Cross-driver | B11: =COUNTIF('Source Registry'!$F$2:$F$300,$A11) -> 44 | C11: =COUNTIFS('Source Registry'!$F$2:$F$300,$A11,'Source Registry'!$I$2:$I$300,1) -> 23 | D11: =COUNTIFS('Source Registry'!$F$2:$F$300,$A11,'Source Registry'!$I$2:$I$300,2) -> 8 | E11: =COUNTIFS('Source Registry'!$F$2:$F$300,$A11,'Source Registry'!$I$2:$I$300,3) -> 13 | F11: =COUNTIFS('Source Registry'!$F$2:$F$300,$A11,'Source Registry'!$G$2:$G$300,"Near-term (1-2 seasons)") -> 0 | G11: =COUNTIFS('Source Registry'!$F$2:$F$300,$A11,'Source Registry'!$G$2:$G$300,"Long-term (3-10 yrs)") -> 3 | H11: =COUNTIFS('Source Registry'!$F$2:$F$300,$A11,'Source Registry'!$G$2:$G$300,"Both") -> 41 | I11: =COUNTIFS('Source Registry'!$F$2:$F$300,$A11,'Source Registry'!$T$2:$T$300,"Connected")+COUNTIFS('Source Registry'!$F$2:$F$300,$A11,'Source Registry'!$T$2:$T$300,"Live in agent") -> 0 | J11: =IF(B11=0,0,I11/B11) -> 0
A12: Core S&D (baseline) | B12: =COUNTIF('Source Registry'!$F$2:$F$300,$A12) -> 36 | C12: =COUNTIFS('Source Registry'!$F$2:$F$300,$A12,'Source Registry'!$I$2:$I$300,1) -> 19 | D12: =COUNTIFS('Source Registry'!$F$2:$F$300,$A12,'Source Registry'!$I$2:$I$300,2) -> 13 | E12: =COUNTIFS('Source Registry'!$F$2:$F$300,$A12,'Source Registry'!$I$2:$I$300,3) -> 4 | F12: =COUNTIFS('Source Registry'!$F$2:$F$300,$A12,'Source Registry'!$G$2:$G$300,"Near-term (1-2 seasons)") -> 29 | G12: =COUNTIFS('Source Registry'!$F$2:$F$300,$A12,'Source Registry'!$G$2:$G$300,"Long-term (3-10 yrs)") -> 2 | H12: =COUNTIFS('Source Registry'!$F$2:$F$300,$A12,'Source Registry'!$G$2:$G$300,"Both") -> 5 | I12: =COUNTIFS('Source Registry'!$F$2:$F$300,$A12,'Source Registry'!$T$2:$T$300,"Connected")+COUNTIFS('Source Registry'!$F$2:$F$300,$A12,'Source Registry'!$T$2:$T$300,"Live in agent") -> 0 | J12: =IF(B12=0,0,I12/B12) -> 0
A13: Total | B13: =SUM(B5:B12) -> 188 | C13: =SUM(C5:C12) -> 112 | D13: =SUM(D5:D12) -> 50 | E13: =SUM(E5:E12) -> 26 | F13: =SUM(F5:F12) -> 66 | G13: =SUM(G5:G12) -> 36 | H13: =SUM(H5:H12) -> 86 | I13: =SUM(I5:I12) -> 0 | J13: =IF(B13=0,0,I13/B13) -> 0
A14: Check: total should equal the number of registry rows | B14: =COUNTA('Source Registry'!$A$2:$A$300) -> 188 | C14: =IF(B13=B14,"OK","Check driver labels") -> OK
A16: Coverage by commodity group
A17: Commodity group | B17: Total sources | C17: Authority 1 | D17: Authority 2 | E17: Authority 3 | F17: Price & market sources | G17: Trade flow sources | H17: Analyst sources | I17: Policy sources
A18: Cross-commodity | B18: =COUNTIF('Source Registry'!$D$2:$D$300,$A18) -> 120 | C18: =COUNTIFS('Source Registry'!$D$2:$D$300,$A18,'Source Registry'!$I$2:$I$300,1) -> 78 | D18: =COUNTIFS('Source Registry'!$D$2:$D$300,$A18,'Source Registry'!$I$2:$I$300,2) -> 32 | E18: =COUNTIFS('Source Registry'!$D$2:$D$300,$A18,'Source Registry'!$I$2:$I$300,3) -> 10 | F18: =COUNTIFS('Source Registry'!$D$2:$D$300,$A18,'Source Registry'!$E$2:$E$300,"Price & market") -> 1 | G18: =COUNTIFS('Source Registry'!$D$2:$D$300,$A18,'Source Registry'!$E$2:$E$300,"Trade flow") -> 5 | H18: =COUNTIFS('Source Registry'!$D$2:$D$300,$A18,'Source Registry'!$E$2:$E$300,"Analyst") -> 4 | I18: =COUNTIFS('Source Registry'!$D$2:$D$300,$A18,'Source Registry'!$E$2:$E$300,"Policy") -> 34
A19: Dairy | B19: =COUNTIF('Source Registry'!$D$2:$D$300,$A19) -> 12 | C19: =COUNTIFS('Source Registry'!$D$2:$D$300,$A19,'Source Registry'!$I$2:$I$300,1) -> 6 | D19: =COUNTIFS('Source Registry'!$D$2:$D$300,$A19,'Source Registry'!$I$2:$I$300,2) -> 4 | E19: =COUNTIFS('Source Registry'!$D$2:$D$300,$A19,'Source Registry'!$I$2:$I$300,3) -> 2 | F19: =COUNTIFS('Source Registry'!$D$2:$D$300,$A19,'Source Registry'!$E$2:$E$300,"Price & market") -> 4 | G19: =COUNTIFS('Source Registry'!$D$2:$D$300,$A19,'Source Registry'!$E$2:$E$300,"Trade flow") -> 1 | H19: =COUNTIFS('Source Registry'!$D$2:$D$300,$A19,'Source Registry'!$E$2:$E$300,"Analyst") -> 1 | I19: =COUNTIFS('Source Registry'!$D$2:$D$300,$A19,'Source Registry'!$E$2:$E$300,"Policy") -> 2
A20: Grains & oilseeds | B20: =COUNTIF('Source Registry'!$D$2:$D$300,$A20) -> 14 | C20: =COUNTIFS('Source Registry'!$D$2:$D$300,$A20,'Source Registry'!$I$2:$I$300,1) -> 7 | D20: =COUNTIFS('Source Registry'!$D$2:$D$300,$A20,'Source Registry'!$I$2:$I$300,2) -> 4 | E20: =COUNTIFS('Source Registry'!$D$2:$D$300,$A20,'Source Registry'!$I$2:$I$300,3) -> 3 | F20: =COUNTIFS('Source Registry'!$D$2:$D$300,$A20,'Source Registry'!$E$2:$E$300,"Price & market") -> 1 | G20: =COUNTIFS('Source Registry'!$D$2:$D$300,$A20,'Source Registry'!$E$2:$E$300,"Trade flow") -> 1 | H20: =COUNTIFS('Source Registry'!$D$2:$D$300,$A20,'Source Registry'!$E$2:$E$300,"Analyst") -> 0 | I20: =COUNTIFS('Source Registry'!$D$2:$D$300,$A20,'Source Registry'!$E$2:$E$300,"Policy") -> 4
A21: Livestock & poultry | B21: =COUNTIF('Source Registry'!$D$2:$D$300,$A21) -> 15 | C21: =COUNTIFS('Source Registry'!$D$2:$D$300,$A21,'Source Registry'!$I$2:$I$300,1) -> 6 | D21: =COUNTIFS('Source Registry'!$D$2:$D$300,$A21,'Source Registry'!$I$2:$I$300,2) -> 3 | E21: =COUNTIFS('Source Registry'!$D$2:$D$300,$A21,'Source Registry'!$I$2:$I$300,3) -> 6 | F21: =COUNTIFS('Source Registry'!$D$2:$D$300,$A21,'Source Registry'!$E$2:$E$300,"Price & market") -> 2 | G21: =COUNTIFS('Source Registry'!$D$2:$D$300,$A21,'Source Registry'!$E$2:$E$300,"Trade flow") -> 0 | H21: =COUNTIFS('Source Registry'!$D$2:$D$300,$A21,'Source Registry'!$E$2:$E$300,"Analyst") -> 2 | I21: =COUNTIFS('Source Registry'!$D$2:$D$300,$A21,'Source Registry'!$E$2:$E$300,"Policy") -> 8
A22: Specialty crops | B22: =COUNTIF('Source Registry'!$D$2:$D$300,$A22) -> 5 | C22: =COUNTIFS('Source Registry'!$D$2:$D$300,$A22,'Source Registry'!$I$2:$I$300,1) -> 3 | D22: =COUNTIFS('Source Registry'!$D$2:$D$300,$A22,'Source Registry'!$I$2:$I$300,2) -> 1 | E22: =COUNTIFS('Source Registry'!$D$2:$D$300,$A22,'Source Registry'!$I$2:$I$300,3) -> 1 | F22: =COUNTIFS('Source Registry'!$D$2:$D$300,$A22,'Source Registry'!$E$2:$E$300,"Price & market") -> 1 | G22: =COUNTIFS('Source Registry'!$D$2:$D$300,$A22,'Source Registry'!$E$2:$E$300,"Trade flow") -> 0 | H22: =COUNTIFS('Source Registry'!$D$2:$D$300,$A22,'Source Registry'!$E$2:$E$300,"Analyst") -> 0 | I22: =COUNTIFS('Source Registry'!$D$2:$D$300,$A22,'Source Registry'!$E$2:$E$300,"Policy") -> 3
A23: Inputs | B23: =COUNTIF('Source Registry'!$D$2:$D$300,$A23) -> 6 | C23: =COUNTIFS('Source Registry'!$D$2:$D$300,$A23,'Source Registry'!$I$2:$I$300,1) -> 2 | D23: =COUNTIFS('Source Registry'!$D$2:$D$300,$A23,'Source Registry'!$I$2:$I$300,2) -> 3 | E23: =COUNTIFS('Source Registry'!$D$2:$D$300,$A23,'Source Registry'!$I$2:$I$300,3) -> 1 | F23: =COUNTIFS('Source Registry'!$D$2:$D$300,$A23,'Source Registry'!$E$2:$E$300,"Price & market") -> 3 | G23: =COUNTIFS('Source Registry'!$D$2:$D$300,$A23,'Source Registry'!$E$2:$E$300,"Trade flow") -> 0 | H23: =COUNTIFS('Source Registry'!$D$2:$D$300,$A23,'Source Registry'!$E$2:$E$300,"Analyst") -> 0 | I23: =COUNTIFS('Source Registry'!$D$2:$D$300,$A23,'Source Registry'!$E$2:$E$300,"Policy") -> 2
A24: Farm economy | B24: =COUNTIF('Source Registry'!$D$2:$D$300,$A24) -> 10 | C24: =COUNTIFS('Source Registry'!$D$2:$D$300,$A24,'Source Registry'!$I$2:$I$300,1) -> 7 | D24: =COUNTIFS('Source Registry'!$D$2:$D$300,$A24,'Source Registry'!$I$2:$I$300,2) -> 1 | E24: =COUNTIFS('Source Registry'!$D$2:$D$300,$A24,'Source Registry'!$I$2:$I$300,3) -> 2 | F24: =COUNTIFS('Source Registry'!$D$2:$D$300,$A24,'Source Registry'!$E$2:$E$300,"Price & market") -> 0 | G24: =COUNTIFS('Source Registry'!$D$2:$D$300,$A24,'Source Registry'!$E$2:$E$300,"Trade flow") -> 0 | H24: =COUNTIFS('Source Registry'!$D$2:$D$300,$A24,'Source Registry'!$E$2:$E$300,"Analyst") -> 2 | I24: =COUNTIFS('Source Registry'!$D$2:$D$300,$A24,'Source Registry'!$E$2:$E$300,"Policy") -> 1
A25: Ownership | B25: =COUNTIF('Source Registry'!$D$2:$D$300,$A25) -> 6 | C25: =COUNTIFS('Source Registry'!$D$2:$D$300,$A25,'Source Registry'!$I$2:$I$300,1) -> 3 | D25: =COUNTIFS('Source Registry'!$D$2:$D$300,$A25,'Source Registry'!$I$2:$I$300,2) -> 2 | E25: =COUNTIFS('Source Registry'!$D$2:$D$300,$A25,'Source Registry'!$I$2:$I$300,3) -> 1 | F25: =COUNTIFS('Source Registry'!$D$2:$D$300,$A25,'Source Registry'!$E$2:$E$300,"Price & market") -> 0 | G25: =COUNTIFS('Source Registry'!$D$2:$D$300,$A25,'Source Registry'!$E$2:$E$300,"Trade flow") -> 0 | H25: =COUNTIFS('Source Registry'!$D$2:$D$300,$A25,'Source Registry'!$E$2:$E$300,"Analyst") -> 1 | I25: =COUNTIFS('Source Registry'!$D$2:$D$300,$A25,'Source Registry'!$E$2:$E$300,"Policy") -> 0
A27: Note: Cross-commodity sources (WASDE, PSD, GATS) cover every group, so a group with few direct rows is not necessarily thin; check its commodity-specific price and trade sources.
A29: Independence: how many sources are real, separate signals
A30: Origin | B30: Sources | C30: Independent: Yes | D30: Partial | E30: No
A31: Original measurement | B31: =COUNTIF('Source Registry'!$O$2:$O$300,$A31) -> 99 | C31: =COUNTIFS('Source Registry'!$O$2:$O$300,$A31,'Source Registry'!$R$2:$R$300,"Yes") -> 98 | D31: =COUNTIFS('Source Registry'!$O$2:$O$300,$A31,'Source Registry'!$R$2:$R$300,"Partial") -> 1 | E31: =COUNTIFS('Source Registry'!$O$2:$O$300,$A31,'Source Registry'!$R$2:$R$300,"No") -> 0
A32: Market-generated | B32: =COUNTIF('Source Registry'!$O$2:$O$300,$A32) -> 10 | C32: =COUNTIFS('Source Registry'!$O$2:$O$300,$A32,'Source Registry'!$R$2:$R$300,"Yes") -> 8 | D32: =COUNTIFS('Source Registry'!$O$2:$O$300,$A32,'Source Registry'!$R$2:$R$300,"Partial") -> 2 | E32: =COUNTIFS('Source Registry'!$O$2:$O$300,$A32,'Source Registry'!$R$2:$R$300,"No") -> 0
A33: Derived | B33: =COUNTIF('Source Registry'!$O$2:$O$300,$A33) -> 35 | C33: =COUNTIFS('Source Registry'!$O$2:$O$300,$A33,'Source Registry'!$R$2:$R$300,"Yes") -> 1 | D33: =COUNTIFS('Source Registry'!$O$2:$O$300,$A33,'Source Registry'!$R$2:$R$300,"Partial") -> 18 | E33: =COUNTIFS('Source Registry'!$O$2:$O$300,$A33,'Source Registry'!$R$2:$R$300,"No") -> 16
A34: Mixed | B34: =COUNTIF('Source Registry'!$O$2:$O$300,$A34) -> 33 | C34: =COUNTIFS('Source Registry'!$O$2:$O$300,$A34,'Source Registry'!$R$2:$R$300,"Yes") -> 3 | D34: =COUNTIFS('Source Registry'!$O$2:$O$300,$A34,'Source Registry'!$R$2:$R$300,"Partial") -> 29 | E34: =COUNTIFS('Source Registry'!$O$2:$O$300,$A34,'Source Registry'!$R$2:$R$300,"No") -> 1
A35: Opinion | B35: =COUNTIF('Source Registry'!$O$2:$O$300,$A35) -> 11 | C35: =COUNTIFS('Source Registry'!$O$2:$O$300,$A35,'Source Registry'!$R$2:$R$300,"Yes") -> 0 | D35: =COUNTIFS('Source Registry'!$O$2:$O$300,$A35,'Source Registry'!$R$2:$R$300,"Partial") -> 0 | E35: =COUNTIFS('Source Registry'!$O$2:$O$300,$A35,'Source Registry'!$R$2:$R$300,"No") -> 11
A37: Registered sources | B37: =COUNTA('Source Registry'!$A$2:$A$300) -> 188
A38: Distinct root sources | B38: =SUMPRODUCT(('Source Registry'!$Q$2:$Q$300<>"")/(COUNTIF('Source Registry'!$Q$2:$Q$300,'Source Registry'!$Q$2:$Q$300)+('Source Registry'!$Q$2:$Q$300=""))) -> 161
A39: Sources that echo another (Independent = No) | B39: =COUNTIF('Source Registry'!$R$2:$R$300,"No") -> 28
A40: Share of sources that are separate roots | B40: =IF(B37=0,0,B38/B37) -> 0.85638298

Sheet Root Check
A1: Root check: are these sources really independent?
A2: Type up to five source IDs from the registry that support one claim (yellow cells). The sheet shows each source's root and whether it builds on the others. The three IDs shown are an example of an echo; replace them.
A4: Slot | B4: Source ID | C4: Source | D4: Origin | E4: Root ID | F4: Root source | G4: Independent signal | H4: Depends on | I4: Builds on another selected source
A5: 1 | B5: S007 | C5: =IF(B5="","",IFERROR(INDEX('Source Registry'!$B$2:$B$300,MATCH(B5,'Source Registry'!$A$2:$A$300,0)),"ID not found")) -> ERS Dairy and Livestock Outlooks | D5: =IF(B5="","",IFERROR(INDEX('Source Registry'!$O$2:$O$300,MATCH(B5,'Source Registry'!$A$2:$A$300,0))&"","")) -> Derived | E5: =IF(B5="","",IFERROR(INDEX('Source Registry'!$Q$2:$Q$300,MATCH(B5,'Source Registry'!$A$2:$A$300,0))&"","")) -> S001 | F5: =IF(E5="","",IFERROR(INDEX('Source Registry'!$B$2:$B$300,MATCH(E5,'Source Registry'!$A$2:$A$300,0)),"")) -> WASDE | G5: =IF(B5="","",IFERROR(INDEX('Source Registry'!$R$2:$R$300,MATCH(B5,'Source Registry'!$A$2:$A$300,0))&"","")) -> No | H5: =IF(B5="","",IFERROR(INDEX('Source Registry'!$P$2:$P$300,MATCH(B5,'Source Registry'!$A$2:$A$300,0))&"","")) -> S001, S006, S017, S005 | I5: =IF(B5="","",SUMPRODUCT(($B$5:$B$9<>"")*($B$5:$B$9<>B5)*ISNUMBER(SEARCH($B$5:$B$9,H5)))) -> 1
